Workbook

Sheet Cobra Web
A1: DOMAIN | B1: TABLE_NAME | C1: COLUMN_NAME | D1: COLUMN_ORDER | E1: DATA_TYPE | F1: SQL_DATA_TYPE | G1: DATA_LENGTH | H1: SCALE | I1: NOT_NULL | J1: DEFAULT | K1: PRIMARY_KEY | L1: NATURAL_KEY | M1: FKEY_TABLE | N1: FKEY_COLUMN | O1: FKEY_CARDINALITY | P1: DESCRIPTION | Q1: JAVA_PROPERTY_NAME | R1: JAVA_DATA_TYPE | S1: COLUMN_FLAGS | T1: TABLE_DESCRIPTION | U1: TABLE_FLAGS | V1: COMMENTS | W1: Table.Column | X1: Found in Mapping? | Y1: Old Table.Column | Z1: Old Data Type | AA1: Old Data Length | AB1: Migrate from Cobra DeskTop Table
A2: Codes | B2: CODE | C2: ROW_UID | D2: 1 | E2: GUID | F2: =VLOOKUP($E2,'Data Type Lookup'!$A$1:$C$21,2,FALSE) -> RAW(16) | I2: Y | K2: Y | P2: Unique Code Identifier. | Q2: uid | R2: =VLOOKUP(E2,'Data Type Lookup'!$A$1:$C$21,3,FALSE) -> java.util.UUID | S2: 3 | W2: =_xlfn.CONCAT(B2,".",C2) -> CODE.ROW_UID | X2: =VLOOKUP(W2,ColumnMapping[New Table.Column],1,) -> CODE.ROW_UID | Y2: =_xlfn.XLOOKUP(Table6[[#This Row],[Table.Column]],ColumnMapping[Add Column Name],ColumnMapping[Old Table.Column],"",0,1) | Z2: =_xlfn.XLOOKUP(Table6[[#This Row],[Old Table.Column]],Cobra8.6[Table.Column],Cobra8.6[TYPE],"",0,1) | AA2: =_xlfn.XLOOKUP(Table6[[#This Row],[Old Table.Column]],Cobra8.6[Table.Column],Cobra8.6[LENGTH],"",0,1)
A3: Codes | B3: CODE | C3: SEQUENCE | D3: 2 | E3: LONGINT | F3: =VLOOKUP($E3,'Data Type Lookup'!$A$1:$C$21,2,FALSE) -> NUMBER(19,0) | I3: Y | J3: 0 | P3: Concurrency Control Identifier. | Q3: sequence | R3: =VLOOKUP(E3,'Data Type Lookup'!$A$1:$C$21,3,FALSE) -> Long | S3: 3 | W3: =_xlfn.CONCAT(B3,".",C3) -> CODE.SEQUENCE | X3: =VLOOKUP(W3,ColumnMapping[New Table.Column],1,) -> CODE.SEQUENCE | Y3: =_xlfn.XLOOKUP(Table6[[#This Row],[Table.Column]],ColumnMapping[Add Column Name],ColumnMapping[Old Table.Column],"",0,1) | Z3: =_xlfn.XLOOKUP(Table6[[#This Row],[Old Table.Column]],Cobra8.6[Table.Column],Cobra8.6[TYPE],"",0,1) | AA3: =_xlfn.XLOOKUP(Table6[[#This Row],[Old Table.Column]],Cobra8.6[Table.Column],Cobra8.6[LENGTH],"",0,1)
A4: Codes | B4: CODE | C4: CODE_FILE_UID | D4: 3 | E4: GUID | F4: =VLOOKUP($E4,'Data Type Lookup'!$A$1:$C$21,2,FALSE) -> RAW(16) | I4: Y | L4: Y | M4: CODE_FILE | N4: ROW_UID | O4: 1:N | P4: Unique Identifier of the Code File record. | Q4: codeFile | R4: =VLOOKUP(E4,'Data Type Lookup'!$A$1:$C$21,3,FALSE) -> java.util.UUID | S4: 1 | W4: =_xlfn.CONCAT(B4,".",C4) -> CODE.CODE_FILE_UID | X4: =VLOOKUP(W4,ColumnMapping[New Table.Column],1,) -> CODE.CODE_FILE_UID | Y4: =_xlfn.XLOOKUP(Table6[[#This Row],[Table.Column]],ColumnMapping[Add Column Name],ColumnMapping[Old Table.Column],"",0,1) | Z4: =_xlfn.XLOOKUP(Table6[[#This Row],[Old Table.Column]],Cobra8.6[Table.Column],Cobra8.6[TYPE],"",0,1) | AA4: =_xlfn.XLOOKUP(Table6[[#This Row],[Old Table.Column]],Cobra8.6[Table.Column],Cobra8.6[LENGTH],"",0,1)
A5: Codes | B5: CODE | C5: PARENT_CODE_UID | D5: 4 | E5: GUID | F5: =VLOOKUP($E5,'Data Type Lookup'!$A$1:$C$21,2,FALSE) -> RAW(16) | L5: Y | M5: CODE | N5: ROW_UID | O5: 1:N | P5: Unique Identifier of the Parent Code record. | Q5: parentCode | R5: =VLOOKUP(E5,'Data Type Lookup'!$A$1:$C$21,3,FALSE) -> java.util.UUID | S5: 1 | W5: =_xlfn.CONCAT(B5,".",C5) -> CODE.PARENT_CODE_UID | X5: =VLOOKUP(W5,ColumnMapping[New Table.Column],1,) -> CODE.PARENT_CODE_UID | Y5: =_xlfn.XLOOKUP(Table6[[#This Row],[Table.Column]],ColumnMapping[Add Column Name],ColumnMapping[Old Table.Column],"",0,1) | Z5: =_xlfn.XLOOKUP(Table6[[#This Row],[Old Table.Column]],Cobra8.6[Table.Column],Cobra8.6[TYPE],"",0,1) | AA5: =_xlfn.XLOOKUP(Table6[[#This Row],[Old Table.Column]],Cobra8.6[Table.Column],Cobra8.6[LENGTH],"",0,1)
A6: Codes | B6: CODE | C6: NAME | D6: 5 | E6: NTEXT | F6: =VLOOKUP($E6,'Data Type Lookup'!$A$1:$C$21,2,FALSE) -> NVARCHAR2 | G6: 100 | I6: Y | L6: Y | P6: Code Name. | Q6: name | R6: =VLOOKUP(E6,'Data Type Lookup'!$A$1:$C$21,3,FALSE) -> String | W6: =_xlfn.CONCAT(B6,".",C6) -> CODE.NAME | X6: =VLOOKUP(W6,ColumnMapping[New Table.Column],1,) -> CODE.NAME | Y6: =_xlfn.XLOOKUP(Table6[[#This Row],[Table.Column]],ColumnMapping[Add Column Name],ColumnMapping[Old Table.Column],"",0,1) | Z6: =_xlfn.XLOOKUP(Table6[[#This Row],[Old Table.Column]],Cobra8.6[Table.Column],Cobra8.6[TYPE],"",0,1) | AA6: =_xlfn.XLOOKUP(Table6[[#This Row],[Old Table.Column]],Cobra8.6[Table.Column],Cobra8.6[LENGTH],"",0,1)
A7: Codes | B7: CODE | C7: CODE_LEVEL | D7: 6 | E7: SHORTINT | F7: =VLOOKUP($E7,'Data Type Lookup'!$A$1:$C$21,2,FALSE) -> NUMBER(5,0) | J7: 1 | P7: Code hierarchy level. | Q7: codeLevel | R7: =VLOOKUP(E7,'Data Type Lookup'!$A$1:$C$21,3,FALSE) -> Short | W7: =_xlfn.CONCAT(B7,".",C7) -> CODE.CODE_LEVEL | X7: =VLOOKUP(W7,ColumnMapping[New Table.Column],1,) -> CODE.CODE_LEVEL | Y7: =_xlfn.XLOOKUP(Table6[[#This Row],[Table.Column]],ColumnMapping[Add Column Name],ColumnMapping[Old Table.Column],"",0,1) | Z7: =_xlfn.XLOOKUP(Table6[[#This Row],[Old Table.Column]],Cobra8.6[Table.Column],Cobra8.6[TYPE],"",0,1) | AA7: =_xlfn.XLOOKUP(Table6[[#This Row],[Old Table.Column]],Cobra8.6[Table.Column],Cobra8.6[LENGTH],"",0,1)
A8: Codes | B8: CODE | C8: CHILD_COUNT | D8: 7 | E8: SHORTINT | F8: =VLOOKUP($E8,'Data Type Lookup'!$A$1:$C$21,2,FALSE) -> NUMBER(5,0) | J8: 0 | P8: Parent Code child count. | Q8: childCount | R8: =VLOOKUP(E8,'Data Type Lookup'!$A$1:$C$21,3,FALSE) -> Short | W8: =_xlfn.CONCAT(B8,".",C8) -> CODE.CHILD_COUNT | X8: =VLOOKUP(W8,ColumnMapping[New Table.Column],1,) -> CODE.CHILD_COUNT | Y8: =_xlfn.XLOOKUP(Table6[[#This Row],[Table.Column]],ColumnMapping[Add Column Name],ColumnMapping[Old Table.Column],"",0,1) | Z8: =_xlfn.XLOOKUP(Table6[[#This Row],[Old Table.Column]],Cobra8.6[Table.Column],Cobra8.6[TYPE],"",0,1) | AA8: =_xlfn.XLOOKUP(Table6[[#This Row],[Old Table.Column]],Cobra8.6[Table.Column],Cobra8.6[LENGTH],"",0,1)
A9: Codes | B9: CODE | C9: CHILD_POS | D9: 8 | E9: SHORTINT | F9: =VLOOKUP($E9,'Data Type Lookup'!$A$1:$C$21,2,FALSE) -> NUMBER(5,0) | J9: 0 | P9: Child Code position. | Q9: childPos | R9: =VLOOKUP(E9,'Data Type Lookup'!$A$1:$C$21,3,FALSE) -> Short | W9: =_xlfn.CONCAT(B9,".",C9) -> CODE.CHILD_POS | X9: =VLOOKUP(W9,ColumnMapping[New Table.Column],1,) -> CODE.CHILD_POS | Y9: =_xlfn.XLOOKUP(Table6[[#This Row],[Table.Column]],ColumnMapping[Add Column Name],ColumnMapping[Old Table.Column],"",0,1) | Z9: =_xlfn.XLOOKUP(Table6[[#This Row],[Old Table.Column]],Cobra8.6[Table.Column],Cobra8.6[TYPE],"",0,1) | AA9: =_xlfn.XLOOKUP(Table6[[#This Row],[Old Table.Column]],Cobra8.6[Table.Column],Cobra8.6[LENGTH],"",0,1)
A10: Codes | B10: CODE | C10: CREATED_BY_USER_UID | D10: 9 | E10: GUID | F10: =VLOOKUP($E10,'Data Type Lookup'!$A$1:$C$21,2,FALSE) -> RAW(16) | I10: Y | P10: The User that created the Code. | Q10: createdBy | R10: =VLOOKUP(E10,'Data Type Lookup'!$A$1:$C$21,3,FALSE) -> java.util.UUID | S10: 2 | W10: =_xlfn.CONCAT(B10,".",C10) -> CODE.CREATED_BY_USER_UID | X10: =VLOOKUP(W10,ColumnMapping[New Table.Column],1,) -> CODE.CREATED_BY_USER_UID | Y10: =_xlfn.XLOOKUP(Table6[[#This Row],[Table.Column]],ColumnMapping[Add Column Name],ColumnMapping[Old Table.Column],"",0,1) | Z10: =_xlfn.XLOOKUP(Table6[[#This Row],[Old Table.Column]],Cobra8.6[Table.Column],Cobra8.6[TYPE],"",0,1) | AA10: =_xlfn.XLOOKUP(Table6[[#This Row],[Old Table.Column]],Cobra8.6[Table.Column],Cobra8.6[LENGTH],"",0,1)
A11: Codes | B11: CODE | C11: CREATED_DATE | D11: 10 | E11: TIMESTAMP | F11: =VLOOKUP($E11,'Data Type Lookup'!$A$1:$C$21,2,FALSE) -> TIMESTAMP | I11: Y | P11: Date the Code was created. | Q11: createdDate | R11: =VLOOKUP(E11,'Data Type Lookup'!$A$1:$C$21,3,FALSE) -> java.time.Instant | S11: 2 | W11: =_xlfn.CONCAT(B11,".",C11) -> CODE.CREATED_DATE | X11: =VLOOKUP(W11,ColumnMapping[New Table.Column],1,) -> CODE.CREATED_DATE | Y11: =_xlfn.XLOOKUP(Table6[[#This Row],[Table.Column]],ColumnMapping[Add Column Name],ColumnMapping[Old Table.Column],"",0,1) | Z11: =_xlfn.XLOOKUP(Table6[[#This Row],[Old Table.Column]],Cobra8.6[Table.Column],Cobra8.6[TYPE],"",0,1) | AA11: =_xlfn.XLOOKUP(Table6[[#This Row],[Old Table.Column]],Cobra8.6[Table.Column],Cobra8.6[LENGTH],"",0,1)
A12: Codes | B12: CODE | C12: LAST_MODIFIED_BY_USER_UID | D12: 11 | E12: GUID | F12: =VLOOKUP($E12,'Data Type Lookup'!$A$1:$C$21,2,FALSE) -> RAW(16) | I12: Y | P12: The User that last changed the Code. | Q12: lastModifiedBy | R12: =VLOOKUP(E12,'Data Type Lookup'!$A$1:$C$21,3,FALSE) -> java.util.UUID | S12: 2 | W12: =_xlfn.CONCAT(B12,".",C12) -> CODE.LAST_MODIFIED_BY_USER_UID | X12: =VLOOKUP(W12,ColumnMapping[New Table.Column],1,) -> CODE.LAST_MODIFIED_BY_USER_UID | Y12: =_xlfn.XLOOKUP(Table6[[#This Row],[Table.Column]],ColumnMapping[Add Column Name],ColumnMapping[Old Table.Column],"",0,1) | Z12: =_xlfn.XLOOKUP(Table6[[#This Row],[Old Table.Column]],Cobra8.6[Table.Column],Cobra8.6[TYPE],"",0,1) | AA12: =_xlfn.XLOOKUP(Table6[[#This Row],[Old Table.Column]],Cobra8.6[Table.Column],Cobra8.6[LENGTH],"",0,1)
A13: Codes | B13: CODE | C13: LAST_MODIFIED_DATE | D13: 12 | E13: TIMESTAMP | F13: =VLOOKUP($E13,'Data Type Lookup'!$A$1:$C$21,2,FALSE) -> TIMESTAMP | I13: Y | P13: Date the last change was made to the Code. | Q13: lastModifiedDate | R13: =VLOOKUP(E13,'Data Type Lookup'!$A$1:$C$21,3,FALSE) -> java.time.Instant | S13: 2 | W13: =_xlfn.CONCAT(B13,".",C13) -> CODE.LAST_MODIFIED_DATE | X13: =VLOOKUP(W13,ColumnMapping[New Table.Column],1,) -> CODE.LAST_MODIFIED_DATE | Y13: =_xlfn.XLOOKUP(Table6[[#This Row],[Table.Column]],ColumnMapping[Add Column Name],ColumnMapping[Old Table.Column],"",0,1) | Z13: =_xlfn.XLOOKUP(Table6[[#This Row],[Old Table.Column]],Cobra8.6[Table.Column],Cobra8.6[TYPE],"",0,1) | AA13: =_xlfn.XLOOKUP(Table6[[#This Row],[Old Table.Column]],Cobra8.6[Table.Column],Cobra8.6[LENGTH],"",0,1)
A14: Codes | B14: CODE | C14: DESCRIPTION | D14: 13 | E14: NTEXT | F14: =VLOOKUP($E14,'Data Type Lookup'!$A$1:$C$21,2,FALSE) -> NVARCHAR2 | G14: 256 | P14: Code Description. | Q14: description | R14: =VLOOKUP(E14,'Data Type Lookup'!$A$1:$C$21,3,FALSE) -> String | W14: =_xlfn.CONCAT(B14,".",C14) -> CODE.DESCRIPTION | X14: =VLOOKUP(W14,ColumnMapping[New Table.Column],1,) -> CODE.DESCRIPTION | Y14: =_xlfn.XLOOKUP(Table6[[#This Row],[Table.Column]],ColumnMapping[Add Column Name],ColumnMapping[Old Table.Column],"",0,1) | Z14: =_xlfn.XLOOKUP(Table6[[#This Row],[Old Table.Column]],Cobra8.6[Table.Column],Cobra8.6[TYPE],"",0,1) | AA14: =_xlfn.XLOOKUP(Table6[[#This Row],[Old Table.Column]],Cobra8.6[Table.Column],Cobra8.6[LENGTH],"",0,1)
A15: Codes | B15: CODE | C15: D1 | D15: 14 | E15: NTEXT | F15: =VLOOKUP($E15,'Data Type Lookup'!$A$1:$C$21,2,FALSE) -> NVARCHAR2 | G15: 59 | W15: =_xlfn.CONCAT(B15,".",C15) -> CODE.D1 | X15: =VLOOKUP(W15,ColumnMapping[New Table.Column],1,) -> #N/A | Y15: =_xlfn.XLOOKUP(Table6[[#This Row],[Table.Column]],ColumnMapping[Add Column Name],ColumnMapping[Old Table.Column],"",0,1) | Z15: =_xlfn.XLOOKUP(Table6[[#This Row],[Old Table.Column]],Cobra8.6[Table.Column],Cobra8.6[TYPE],"",0,1) | AA15: =_xlfn.XLOOKUP(Table6[[#This Row],[Old Table.Column]],Cobra8.6[Table.Column],Cobra8.6[LENGTH],"",0,1)
A16: Codes | B16: CODE | C16: D2 | D16: 15 | E16: NTEXT | F16: =VLOOKUP($E16,'Data Type Lookup'!$A$1:$C$21,2,FALSE) -> NVARCHAR2 | G16: 59 | W16: =_xlfn.CONCAT(B16,".",C16) -> CODE.D2 | X16: =VLOOKUP(W16,ColumnMapping[New Table.Column],1,) -> #N/A | Y16: =_xlfn.XLOOKUP(Table6[[#This Row],[Table.Column]],ColumnMapping[Add Column Name],ColumnMapping[Old Table.Column],"",0,1) | Z16: =_xlfn.XLOOKUP(Table6[[#This Row],[Old Table.Column]],Cobra8.6[Table.Column],Cobra8.6[TYPE],"",0,1) | AA16: =_xlfn.XLOOKUP(Table6[[#This Row],[Old Table.Column]],Cobra8.6[Table.Column],Cobra8.6[LENGTH],"",0,1)
A17: Codes | B17: CODE | C17: D3 | D17: 16 | E17: NTEXT | F17: =VLOOKUP($E17,'Data Type Lookup'!$A$1:$C$21,2,FALSE) -> NVARCHAR2 | G17: 59 | W17: =_xlfn.CONCAT(B17,".",C17) -> CODE.D3 | X17: =VLOOKUP(W17,ColumnMapping[New Table.Column],1,) -> #N/A | Y17: =_xlfn.XLOOKUP(Table6[[#This Row],[Table.Column]],ColumnMapping[Add Column Name],ColumnMapping[Old Table.Column],"",0,1) | Z17: =_xlfn.XLOOKUP(Table6[[#This Row],[Old Table.Column]],Cobra8.6[Table.Column],Cobra8.6[TYPE],"",0,1) | AA17: =_xlfn.XLOOKUP(Table6[[#This Row],[Old Table.Column]],Cobra8.6[Table.Column],Cobra8.6[LENGTH],"",0,1)
A18: Codes | B18: CODE | C18: D4 | D18: 17 | E18: NTEXT | F18: =VLOOKUP($E18,'Data Type Lookup'!$A$1:$C$21,2,FALSE) -> NVARCHAR2 | G18: 59 | W18: =_xlfn.CONCAT(B18,".",C18) -> CODE.D4 | X18: =VLOOKUP(W18,ColumnMapping[New Table.Column],1,) -> #N/A | Y18: =_xlfn.XLOOKUP(Table6[[#This Row],[Table.Column]],ColumnMapping[Add Column Name],ColumnMapping[Old Table.Column],"",0,1) | Z18: =_xlfn.XLOOKUP(Table6[[#This Row],[Old Table.Column]],Cobra8.6[Table.Column],Cobra8.6[TYPE],"",0,1) | AA18: =_xlfn.XLOOKUP(Table6[[#This Row],[Old Table.Column]],Cobra8.6[Table.Column],Cobra8.6[LENGTH],"",0,1)
A19: Codes | B19: CODE | C19: D5 | D19: 18 | E19: NTEXT | F19: =VLOOKUP($E19,'Data Type Lookup'!$A$1:$C$21,2,FALSE) -> NVARCHAR2 | G19: 59 | W19: =_xlfn.CONCAT(B19,".",C19) -> CODE.D5 | X19: =VLOOKUP(W19,ColumnMapping[New Table.Column],1,) -> #N/A | Y19: =_xlfn.XLOOKUP(Table6[[#This Row],[Table.Column]],ColumnMapping[Add Column Name],ColumnMapping[Old Table.Column],"",0,1) | Z19: =_xlfn.XLOOKUP(Table6[[#This Row],[Old Table.Column]],Cobra8.6[Table.Column],Cobra8.6[TYPE],"",0,1) | AA19: =_xlfn.XLOOKUP(Table6[[#This Row],[Old Table.Column]],Cobra8.6[Table.Column],Cobra8.6[LENGTH],"",0,1)
A20: Codes | B20: CODE | C20: D6 | D20: 19 | E20: NTEXT | F20: =VLOOKUP($E20,'Data Type Lookup'!$A$1:$C$21,2,FALSE) -> NVARCHAR2 | G20: 59 | W20: =_xlfn.CONCAT(B20,".",C20) -> CODE.D6 | X20: =VLOOKUP(W20,ColumnMapping[New Table.Column],1,) -> #N/A | Y20: =_xlfn.XLOOKUP(Table6[[#This Row],[Table.Column]],ColumnMapping[Add Column Name],ColumnMapping[Old Table.Column],"",0,1) | Z20: =_xlfn.XLOOKUP(Table6[[#This Row],[Old Table.Column]],Cobra8.6[Table.Column],Cobra8.6[TYPE],"",0,1) | AA20: =_xlfn.XLOOKUP(Table6[[#This Row],[Old Table.Column]],Cobra8.6[Table.Column],Cobra8.6[LENGTH],"",0,1)
A21: Codes | B21: CODE | C21: D7 | D21: 20 | E21: NTEXT | F21: =VLOOKUP($E21,'Data Type Lookup'!$A$1:$C$21,2,FALSE) -> NVARCHAR2 | G21: 59 | W21: =_xlfn.CONCAT(B21,".",C21) -> CODE.D7 | X21: =VLOOKUP(W21,ColumnMapping[New Table.Column],1,) -> #N/A | Y21: =_xlfn.XLOOKUP(Table6[[#This Row],[Table.Column]],ColumnMapping[Add Column Name],ColumnMapping[Old Table.Column],"",0,1) | Z21: =_xlfn.XLOOKUP(Table6[[#This Row],[Old Table.Column]],Cobra8.6[Table.Column],Cobra8.6[TYPE],"",0,1) | AA21: =_xlfn.XLOOKUP(Table6[[#This Row],[Old Table.Column]],Cobra8.6[Table.Column],Cobra8.6[LENGTH],"",0,1)
A22: Codes | B22: CODE | C22: D8 | D22: 21 | E22: NTEXT | F22: =VLOOKUP($E22,'Data Type Lookup'!$A$1:$C$21,2,FALSE) -> NVARCHAR2 | G22: 59 | W22: =_xlfn.CONCAT(B22,".",C22) -> CODE.D8 | X22: =VLOOKUP(W22,ColumnMapping[New Table.Column],1,) -> #N/A | Y22: =_xlfn.XLOOKUP(Table6[[#This Row],[Table.Column]],ColumnMapping[Add Column Name],ColumnMapping[Old Table.Column],"",0,1) | Z22: =_xlfn.XLOOKUP(Table6[[#This Row],[Old Table.Column]],Cobra8.6[Table.Column],Cobra8.6[TYPE],"",0,1) | AA22: =_xlfn.XLOOKUP(Table6[[#This Row],[Old Table.Column]],Cobra8.6[Table.Column],Cobra8.6[LENGTH],"",0,1)
A23: Codes | B23: CODE | C23: D9 | D23: 22 | E23: NTEXT | F23: =VLOOKUP($E23,'Data Type Lookup'!$A$1:$C$21,2,FALSE) -> NVARCHAR2 | G23: 59 | W23: =_xlfn.CONCAT(B23,".",C23) -> CODE.D9 | X23: =VLOOKUP(W23,ColumnMapping[New Table.Column],1,) -> #N/A | Y23: =_xlfn.XLOOKUP(Table6[[#This Row],[Table.Column]],ColumnMapping[Add Column Name],ColumnMapping[Old Table.Column],"",0,1) | Z23: =_xlfn.XLOOKUP(Table6[[#This Row],[Old Table.Column]],Cobra8.6[Table.Column],Cobra8.6[TYPE],"",0,1) | AA23: =_xlfn.XLOOKUP(Table6[[#This Row],[Old Table.Column]],Cobra8.6[Table.Column],Cobra8.6[LENGTH],"",0,1)
A24: Codes | B24: CODE | C24: TAG | D24: 23 | E24: TEXT | F24: =VLOOKUP($E24,'Data Type Lookup'!$A$1:$C$21,2,FALSE) -> VARCHAR2 | G24: 60 | W24: =_xlfn.CONCAT(B24,".",C24) -> CODE.TAG | X24: =VLOOKUP(W24,ColumnMapping[New Table.Column],1,) -> CODE.TAG | Y24: =_xlfn.XLOOKUP(Table6[[#This Row],[Table.Column]],ColumnMapping[Add Column Name],ColumnMapping[Old Table.Column],"",0,1) -> BDNDETL.TAG | Z24: =_xlfn.XLOOKUP(Table6[[#This Row],[Old Table.Column]],Cobra8.6[Table.Column],Cobra8.6[TYPE],"",0,1) -> TEXT | AA24: =_xlfn.XLOOKUP(Table6[[#This Row],[Old Table.Column]],Cobra8.6[Table.Column],Cobra8.6[LENGTH],"",0,1) -> 60
A25: Codes | B25: CODE | C25: BREAKFILE | E25: NTEXT | F25: =VLOOKUP($E25,'Data Type Lookup'!$A$1:$C$21,2,FALSE) -> NVARCHAR2 | G25: 22 | W25: =_xlfn.CONCAT(B25,".",C25) -> CODE.BREAKFILE | X25: =VLOOKUP(W25,ColumnMapping[New Table.Column],1,) -> #N/A | Y25: =_xlfn.XLOOKUP(Table6[[#This Row],[Table.Column]],ColumnMapping[Add Column Name],ColumnMapping[Old Table.Column],"",0,1) -> BDNDETL.BREAKFILE | Z25: =_xlfn.XLOOKUP(Table6[[#This Row],[Old Table.Column]],Cobra8.6[Table.Column],Cobra8.6[TYPE],"",0,1) -> TEXT | AA25: =_xlfn.XLOOKUP(Table6[[#This Row],[Old Table.Column]],Cobra8.6[Table.Column],Cobra8.6[LENGTH],"",0,1) -> 22
A26: Codes | B26: CODE_FILE | C26: ROW_UID | D26: 1 | E26: GUID | F26: =VLOOKUP($E26,'Data Type Lookup'!$A$1:$C$21,2,FALSE) -> RAW(16) | I26: Y | K26: Y | P26: Unique Code File Identifier. | Q26: uid | R26: =VLOOKUP(E26,'Data Type Lookup'!$A$1:$C$21,3,FALSE) -> java.util.UUID | S26: 3 | U26: 8 | W26: =_xlfn.CONCAT(B26,".",C26) -> CODE_FILE.ROW_UID | X26: =VLOOKUP(W26,ColumnMapping[New Table.Column],1,) -> CODE_FILE.ROW_UID | Y26: =_xlfn.XLOOKUP(Table6[[#This Row],[Table.Column]],ColumnMapping[Add Column Name],ColumnMapping[Old Table.Column],"",0,1) | Z26: =_xlfn.XLOOKUP(Table6[[#This Row],[Old Table.Column]],Cobra8.6[Table.Column],Cobra8.6[TYPE],"",0,1) | AA26: =_xlfn.XLOOKUP(Table6[[#This Row],[Old Table.Column]],Cobra8.6[Table.Column],Cobra8.6[LENGTH],"",0,1)
A27: Codes | B27: CODE_FILE | C27: SEQUENCE | D27: 2 | E27: LONGINT | F27: =VLOOKUP($E27,'Data Type Lookup'!$A$1:$C$21,2,FALSE) -> NUMBER(19,0) | I27: Y | J27: 0 | P27: Concurrency Control Identifier. | Q27: sequence | R27: =VLOOKUP(E27,'Data Type Lookup'!$A$1:$C$21,3,FALSE) -> Long | S27: 3 | W27: =_xlfn.CONCAT(B27,".",C27) -> CODE_FILE.SEQUENCE | X27: =VLOOKUP(W27,ColumnMapping[New Table.Column],1,) -> CODE_FILE.SEQUENCE | Y27: =_xlfn.XLOOKUP(Table6[[#This Row],[Table.Column]],ColumnMapping[Add Column Name],ColumnMapping[Old Table.Column],"",0,1) | Z27: =_xlfn.XLOOKUP(Table6[[#This Row],[Old Table.Column]],Cobra8.6[Table.Column],Cobra8.6[TYPE],"",0,1) | AA27: =_xlfn.XLOOKUP(Table6[[#This Row],[Old Table.Column]],Cobra8.6[Table.Column],Cobra8.6[LENGTH],"",0,1)
A28: Codes | B28: CODE_FILE | C28: NAME | D28: 3 | E28: NTEXT | F28: =VLOOKUP($E28,'Data Type Lookup'!$A$1:$C$21,2,FALSE) -> NVARCHAR2 | G28: 100 | L28: Y | P28: Code File Name. | Q28: name | R28: =VLOOKUP(E28,'Data Type Lookup'!$A$1:$C$21,3,FALSE) -> String | W28: =_xlfn.CONCAT(B28,".",C28) -> CODE_FILE.NAME | X28: =VLOOKUP(W28,ColumnMapping[New Table.Column],1,) -> CODE_FILE.NAME | Y28: =_xlfn.XLOOKUP(Table6[[#This Row],[Table.Column]],ColumnMapping[Add Column Name],ColumnMapping[Old Table.Column],"",0,1) | Z28: =_xlfn.XLOOKUP(Table6[[#This Row],[Old Table.Column]],Cobra8.6[Table.Column],Cobra8.6[TYPE],"",0,1) | AA28: =_xlfn.XLOOKUP(Table6[[#This Row],[Old Table.Column]],Cobra8.6[Table.Column],Cobra8.6[LENGTH],"",0,1)
A29: Codes | B29: CODE_FILE | C29: CODE_TYPE | D29: 4 | E29: TEXT | F29: =VLOOKUP($E29,'Data Type Lookup'!$A$1:$C$21,2,FALSE) -> VARCHAR2 | G29: 1 | I29: Y | P29: Code File Code Type. Supported values are P or N. | Q29: codeType | R29: =VLOOKUP(E29,'Data Type Lookup'!$A$1:$C$21,3,FALSE) -> String | W29: =_xlfn.CONCAT(B29,".",C29) -> CODE_FILE.CODE_TYPE | X29: =VLOOKUP(W29,ColumnMapping[New Table.Column],1,) -> CODE_FILE.CODE_TYPE | Y29: =_xlfn.XLOOKUP(Table6[[#This Row],[Table.Column]],ColumnMapping[Add Column Name],ColumnMapping[Old Table.Column],"",0,1) | Z29: =_xlfn.XLOOKUP(Table6[[#This Row],[Old Table.Column]],Cobra8.6[Table.Column],Cobra8.6[TYPE],"",0,1) | AA29: =_xlfn.XLOOKUP(Table6[[#This Row],[Old Table.Column]],Cobra8.6[Table.Column],Cobra8.6[LENGTH],"",0,1)
A30: Codes | B30: CODE_FILE | C30: TH_FLAGS | D30: 6 | E30: TEXT | F30: =VLOOKUP($E30,'Data Type Lookup'!$A$1:$C$21,2,FALSE) -> VARCHAR2 | G30: 10 | I30: Y | J30: ''NNNNNNNNNN'' | P30: Flags to enable Code Threshold Variance options. | Q30: thresholdFlags | R30: =VLOOKUP(E30,'Data Type Lookup'!$A$1:$C$21,3,FALSE) -> String | W30: =_xlfn.CONCAT(B30,".",C30) -> CODE_FILE.TH_FLAGS | X30: =VLOOKUP(W30,ColumnMapping[New Table.Column],1,) -> CODE_FILE.TH_FLAGS | Y30: =_xlfn.XLOOKUP(Table6[[#This Row],[Table.Column]],ColumnMapping[Add Column Name],ColumnMapping[Old Table.Column],"",0,1) -> BREAKDWN.TH_FLAGS | Z30: =_xlfn.XLOOKUP(Table6[[#This Row],[Old Table.Column]],Cobra8.6[Table.Column],Cobra8.6[TYPE],"",0,1) -> TEXT | AA30: =_xlfn.XLOOKUP(Table6[[#This Row],[Old Table.Column]],Cobra8.6[Table.Column],Cobra8.6[LENGTH],"",0,1) -> 10 | AB30: Y
A31: Codes | B31: CODE_FILE | C31: DESCRIPTION | D31: 7 | E31: NTEXT | F31: =VLOOKUP($E31,'Data Type Lookup'!$A$1:$C$21,2,FALSE) -> NVARCHAR2 | G31: 256 | P31: Code File Description. | Q31: description | R31: =VLOOKUP(E31,'Data Type Lookup'!$A$1:$C$21,3,FALSE) -> String | W31: =_xlfn.CONCAT(B31,".",C31) -> CODE_FILE.DESCRIPTION | X31: =VLOOKUP(W31,ColumnMapping[New Table.Column],1,) -> CODE_FILE.DESCRIPTION | Y31: =_xlfn.XLOOKUP(Table6[[#This Row],[Table.Column]],ColumnMapping[Add Column Name],ColumnMapping[Old Table.Column],"",0,1) | Z31: =_xlfn.XLOOKUP(Table6[[#This Row],[Old Table.Column]],Cobra8.6[Table.Column],Cobra8.6[TYPE],"",0,1) | AA31: =_xlfn.XLOOKUP(Table6[[#This Row],[Old Table.Column]],Cobra8.6[Table.Column],Cobra8.6[LENGTH],"",0,1)
A32: Codes | B32: CODE_FILE | C32: FIELD_NAME | D32: 8 | E32: NTEXT | F32: =VLOOKUP($E32,'Data Type Lookup'!$A$1:$C$21,2,FALSE) -> NVARCHAR2 | G32: 30 | I32: Y | P32: Default User Field Name when this Code File is assigned to a User Define Field. | Q32: fieldName | R32: =VLOOKUP(E32,'Data Type Lookup'!$A$1:$C$21,3,FALSE) -> String | W32: =_xlfn.CONCAT(B32,".",C32) -> CODE_FILE.FIELD_NAME | X32: =VLOOKUP(W32,ColumnMapping[New Table.Column],1,) -> CODE_FILE.FIELD_NAME | Y32: =_xlfn.XLOOKUP(Table6[[#This Row],[Table.Column]],ColumnMapping[Add Column Name],ColumnMapping[Old Table.Column],"",0,1) | Z32: =_xlfn.XLOOKUP(Table6[[#This Row],[Old Table.Column]],Cobra8.6[Table.Column],Cobra8.6[TYPE],"",0,1) | AA32: =_xlfn.XLOOKUP(Table6[[#This Row],[Old Table.Column]],Cobra8.6[Table.Column],Cobra8.6[LENGTH],"",0,1)
A33: Codes | B33: CODE_FILE | C33: FIELD_DESCRIPTION | D33: 9 | E33: NTEXT | F33: =VLOOKUP($E33,'Data Type Lookup'!$A$1:$C$21,2,FALSE) -> NVARCHAR2 | G33: 256 | P33: Default Field Description when this Code File is assigned to a User Define Field. | Q33: fieldDescription | R33: =VLOOKUP(E33,'Data Type Lookup'!$A$1:$C$21,3,FALSE) -> String | W33: =_xlfn.CONCAT(B33,".",C33) -> CODE_FILE.FIELD_DESCRIPTION | X33: =VLOOKUP(W33,ColumnMapping[New Table.Column],1,) -> CODE_FILE.FIELD_DESCRIPTION | Y33: =_xlfn.XLOOKUP(Table6[[#This Row],[Table.Column]],ColumnMapping[Add Column Name],ColumnMapping[Old Table.Column],"",0,1) | Z33: =_xlfn.XLOOKUP(Table6[[#This Row],[Old Table.Column]],Cobra8.6[Table.Column],Cobra8.6[TYPE],"",0,1) | AA33: =_xlfn.XLOOKUP(Table6[[#This Row],[Old Table.Column]],Cobra8.6[Table.Column],Cobra8.6[LENGTH],"",0,1)
A34: Codes | B34: CODE_FILE | C34: OWNER_USER_UID | D34: 10 | E34: GUID | F34: =VLOOKUP($E34,'Data Type Lookup'!$A$1:$C$21,2,FALSE) -> RAW(16) | I34: Y | P34: The User that owns the Code File. | Q34: owner | R34: =VLOOKUP(E34,'Data Type Lookup'!$A$1:$C$21,3,FALSE) -> java.util.UUID | W34: =_xlfn.CONCAT(B34,".",C34) -> CODE_FILE.OWNER_USER_UID | X34: =VLOOKUP(W34,ColumnMapping[New Table.Column],1,) -> CODE_FILE.OWNER_USER_UID | Y34: =_xlfn.XLOOKUP(Table6[[#This Row],[Table.Column]],ColumnMapping[Add Column Name],ColumnMapping[Old Table.Column],"",0,1) | Z34: =_xlfn.XLOOKUP(Table6[[#This Row],[Old Table.Column]],Cobra8.6[Table.Column],Cobra8.6[TYPE],"",0,1) | AA34: =_xlfn.XLOOKUP(Table6[[#This Row],[Old Table.Column]],Cobra8.6[Table.Column],Cobra8.6[LENGTH],"",0,1)
A35: Codes | B35: CODE_FILE | C35: CREATED_BY_USER_UID | D35: 11 | E35: GUID | F35: =VLOOKUP($E35,'Data Type Lookup'!$A$1:$C$21,2,FALSE) -> RAW(16) | I35: Y | P35: The User that created the Code File. | Q35: createdBy | R35: =VLOOKUP(E35,'Data Type Lookup'!$A$1:$C$21,3,FALSE) -> java.util.UUID | S35: 2 | W35: =_xlfn.CONCAT(B35,".",C35) -> CODE_FILE.CREATED_BY_USER_UID | X35: =VLOOKUP(W35,ColumnMapping[New Table.Column],1,) -> CODE_FILE.CREATED_BY_USER_UID | Y35: =_xlfn.XLOOKUP(Table6[[#This Row],[Table.Column]],ColumnMapping[Add Column Name],ColumnMapping[Old Table.Column],"",0,1) | Z35: =_xlfn.XLOOKUP(Table6[[#This Row],[Old Table.Column]],Cobra8.6[Table.Column],Cobra8.6[TYPE],"",0,1) | AA35: =_xlfn.XLOOKUP(Table6[[#This Row],[Old Table.Column]],Cobra8.6[Table.Column],Cobra8.6[LENGTH],"",0,1)
A36: Codes | B36: CODE_FILE | C36: CREATED_DATE | D36: 12 | E36: TIMESTAMP | F36: =VLOOKUP($E36,'Data Type Lookup'!$A$1:$C$21,2,FALSE) -> TIMESTAMP | I36: Y | P36: Date the Code File was created. | Q36: createdDate | R36: =VLOOKUP(E36,'Data Type Lookup'!$A$1:$C$21,3,FALSE) -> java.time.Instant | S36: 2 | W36: =_xlfn.CONCAT(B36,".",C36) -> CODE_FILE.CREATED_DATE | X36: =VLOOKUP(W36,ColumnMapping[New Table.Column],1,) -> CODE_FILE.CREATED_DATE | Y36: =_xlfn.XLOOKUP(Table6[[#This Row],[Table.Column]],ColumnMapping[Add Column Name],ColumnMapping[Old Table.Column],"",0,1) | Z36: =_xlfn.XLOOKUP(Table6[[#This Row],[Old Table.Column]],Cobra8.6[Table.Column],Cobra8.6[TYPE],"",0,1) | AA36: =_xlfn.XLOOKUP(Table6[[#This Row],[Old Table.Column]],Cobra8.6[Table.Column],Cobra8.6[LENGTH],"",0,1)
A37: Codes | B37: CODE_FILE | C37: LAST_MODIFIED_BY_USER_UID | D37: 13 | E37: GUID | F37: =VLOOKUP($E37,'Data Type Lookup'!$A$1:$C$21,2,FALSE) -> RAW(16) | I37: Y | P37: The User that last changed the Code File. | Q37: lastModifiedBy | R37: =VLOOKUP(E37,'Data Type Lookup'!$A$1:$C$21,3,FALSE) -> java.util.UUID | S37: 2 | W37: =_xlfn.CONCAT(B37,".",C37) -> CODE_FILE.LAST_MODIFIED_BY_USER_UID | X37: =VLOOKUP(W37,ColumnMapping[New Table.Column],1,) -> CODE_FILE.LAST_MODIFIED_BY_USER_UID | Y37: =_xlfn.XLOOKUP(Table6[[#This Row],[Table.Column]],ColumnMapping[Add Column Name],ColumnMapping[Old Table.Column],"",0,1) | Z37: =_xlfn.XLOOKUP(Table6[[#This Row],[Old Table.Column]],Cobra8.6[Table.Column],Cobra8.6[TYPE],"",0,1) | AA37: =_xlfn.XLOOKUP(Table6[[#This Row],[Old Table.Column]],Cobra8.6[Table.Column],Cobra8.6[LENGTH],"",0,1)
A38: Codes | B38: CODE_FILE | C38: LAST_MODIFIED_DATE | D38: 14 | E38: TIMESTAMP | F38: =VLOOKUP($E38,'Data Type Lookup'!$A$1:$C$21,2,FALSE) -> TIMESTAMP | I38: Y | P38: Date the last change was made to the Code File. | Q38: lastModifiedDate | R38: =VLOOKUP(E38,'Data Type Lookup'!$A$1:$C$21,3,FALSE) -> java.time.Instant | S38: 2 | W38: =_xlfn.CONCAT(B38,".",C38) -> CODE_FILE.LAST_MODIFIED_DATE | X38: =VLOOKUP(W38,ColumnMapping[New Table.Column],1,) -> CODE_FILE.LAST_MODIFIED_DATE | Y38: =_xlfn.XLOOKUP(Table6[[#This Row],[Table.Column]],ColumnMapping[Add Column Name],ColumnMapping[Old Table.Column],"",0,1) | Z38: =_xlfn.XLOOKUP(Table6[[#This Row],[Old Table.Column]],Cobra8.6[Table.Column],Cobra8.6[TYPE],"",0,1) | AA38: =_xlfn.XLOOKUP(Table6[[#This Row],[Old Table.Column]],Cobra8.6[Table.Column],Cobra8.6[LENGTH],"",0,1)
A39: Codes | B39: CODE_FILE | C39: PAD_CHAR | D39: 15 | E39: TEXT | F39: =VLOOKUP($E39,'Data Type Lookup'!$A$1:$C$21,2,FALSE) -> VARCHAR2 | G39: 1 | P39: Padding Character | Q39: =IF(C39="","",LOWER(LEFT(TRIM(C39),FIND("_",TRIM(C39)&"_")-1))&SUBSTITUTE(PROPER(SUBSTITUTE(MID(TRIM(C39),FIND("_",TRIM(C39)&"_"),LEN(TRIM(C39))),"_"," "))," ","")) -> padChar | R39: =VLOOKUP(E39,'Data Type Lookup'!$A$1:$C$21,3,FALSE) -> String | W39: =_xlfn.CONCAT(B39,".",C39) -> CODE_FILE.PAD_CHAR | X39: =VLOOKUP(W39,ColumnMapping[New Table.Column],1,) -> CODE_FILE.PAD_CHAR | Y39: =_xlfn.XLOOKUP(Table6[[#This Row],[Table.Column]],ColumnMapping[Add Column Name],ColumnMapping[Old Table.Column],"",0,1) -> BREAKDWN.PAD_CHAR | Z39: =_xlfn.XLOOKUP(Table6[[#This Row],[Old Table.Column]],Cobra8.6[Table.Column],Cobra8.6[TYPE],"",0,1) -> TEXT | AA39: =_xlfn.XLOOKUP(Table6[[#This Row],[Old Table.Column]],Cobra8.6[Table.Column],Cobra8.6[LENGTH],"",0,1) -> 1 | AB39: Y
A40: Codes | B40: CODE_FILE | C40: MAX_LEVEL | D40: 16 | E40: LONGINT | F40: =VLOOKUP($E40,'Data Type Lookup'!$A$1:$C$21,2,FALSE) -> NUMBER(19,0) | J40: 0 | P40: Maximum Level | Q40: =IF(C40="","",LOWER(LEFT(TRIM(C40),FIND("_",TRIM(C40)&"_")-1))&SUBSTITUTE(PROPER(SUBSTITUTE(MID(TRIM(C40),FIND("_",TRIM(C40)&"_"),LEN(TRIM(C40))),"_"," "))," ","")) -> maxLevel | R40: =VLOOKUP(E40,'Data Type Lookup'!$A$1:$C$21,3,FALSE) -> Long | W40: =_xlfn.CONCAT(B40,".",C40) -> CODE_FILE.MAX_LEVEL | X40: =VLOOKUP(W40,ColumnMapping[New Table.Column],1,) -> CODE_FILE.MAX_LEVEL | Y40: =_xlfn.XLOOKUP(Table6[[#This Row],[Table.Column]],ColumnMapping[Add Column Name],ColumnMapping[Old Table.Column],"",0,1) -> BREAKDWN.MAX_LEVEL | Z40: =_xlfn.XLOOKUP(Table6[[#This Row],[Old Table.Column]],Cobra8.6[Table.Column],Cobra8.6[TYPE],"",0,1) -> INTE | AA40: =_xlfn.XLOOKUP(Table6[[#This Row],[Old Table.Column]],Cobra8.6[Table.Column],Cobra8.6[LENGTH],"",0,1) -> -1 | AB40: Y
...

Sheet Data Type Lookup
A1: Dictionary_Type | B1: Oracle_Data_Type | C1: Java Type
A2: BOOL | B2: NUMBER(1,0) | C2: boolean
A3: BOOLEAN | B3: NUMBER(1,0) | C3: Boolean
A4: DATE | B4: DATE | C4: java.time.Instant
A5: DECIMAL | B5: NUMBER(21,6) | C5: java.math.BigDecimal
A6: ENUM | B6: NUMBER(3,0) | C6: enum
A7: GUID | B7: RAW(16) | C7: java.util.UUID
A8: HOURS | B8: NUMBER(6,2) | C8: java.math.BigDecimal | D8: Number length mappings fromhttps://docs.oracle.com/cd/E23095_01/ACI.93/ACIDataWarehouse/html/s0107keytocolumndatatypenames01.html
A9: INTEGER | B9: NUMBER(10,0) | C9: Integer
A10: JSON | B10: NCLOB | C10: String
A11: JSONO | B11: JSON | C11: String | D11: 0 or 1
A12: LONGINT | B12: NUMBER(19,0) | C12: Long | D12: Byte (0-255) Java recommends Short for this.
A13: MEMO | B13: NCLOB | C13: String | D13: Short Integer (-32768 | 32768)
A14: NTEXT | B14: NVARCHAR2 | C14: String | D14: Long Integer (-2147483648 | 2147483648)
A15: NUMBER | B15: NUMBER | C15: java.math.BigDecimal | D15: 64Bit Integer (-9223372036854775808 | 9223372036854775808)
A16: PERCENT | B16: NUMBER(5,2) | C16: java.math.BigDecimal | D16: JSON type for Oracle 21 and later.
A17: RAW | B17: RAW | C17: byte | D17: JSON type for Oracle 20 and earlier.
A18: SHORTINT | B18: NUMBER(5,0) | C18: Short
A19: TEXT | B19: VARCHAR2 | C19: String | D19: Work in Progress
A20: TIMESTAMP | B20: TIMESTAMP | C20: java.time.Instant
A21: TINYINT | B21: NUMBER(3,0) | C21: Short | D21: Allows non-standard length and scale values to be specified.

Sheet Table Flags
A1: FLAG_NAME | B1: FLAG_VALUE | C1: DESCRIPTION
A2: USER_FIELDS | B2: 0x00000001L | C2: Entity Supports User Defined Fields
A3: USER_NOTES | B3: 0x00000002L | C3: Entity Supports User Defined Note Fields
A4: USER_CODES | B4: 0x00000004L | C4: Entity Supports User Defined Code Fields
A5: ACCESS_CONTROL | B5: 0x00000008L | C5: Entity Supports Access Control Entries
A6: CALCULATED_FIELDS | B6: 0x00000010L | C6: Entity Supports User Defined Calculated Fields
A7: USER_VALIDATIONS | B7: 0x00000020L | C7: Entity Supports User Defined Validations

Sheet Column Flags
A1: FLAG_NAME | B1: FLAG_VALUE | C1: DESCRIPTION
A2: HIDDEN | B2: 0x00000001L | C2: Column is not displayed in the UI.
A3: READ_ONLY | B3: 0x00000002L | C3: Column is Read-Only.
A4: ALLOW_NEGATIVE_DURATION | B4: 0x00000004L | C4: Duration column allows Negative Durations.
A5: ALLOW_PERCENT_DURATION | B5: 0x00000008L | C5: Duration Column allows Percentage Durations.
A6: ALLOW_NEGATIVE_PERCENT | B6: 0x00000010L | C6: Percentage column allows Negative Percentage Values.
A7: USER_DEFINED_FIELD | B7: 0x00000020L | C7: Column is a User defined Field Column.
A8: USER_DEFINED_NOTE_FIELD | B8: 0x00000040L | C8: Column is a User defined Note Field Column.
A9: USER_DEFINED_CODE_FIELD | B9: 0x00000080L | C9: Column is a User defined Code Field Column.
A10: CALCULATED_FIELD | B10: 0x00000100L | C10: Column is a Calculated Field Column.

Sheet Cobra 8.5
A1: TABLE_NAME | B1: TABLE_FLAGS | C1: TABLE_TYPE | D1: FLD_NAME | E1: TYPE | F1: LENGTH | G1: SCALE | H1: COL_FLAGS | I1: SYS_NAME | J1: USR_NAME | K1: STRING_ID | L1: FKEY_TABLE | M1: FKEY_FLD_NAME | N1: FKEY_REQUIRED | O1: FKEY_VIRTUAL | P1: Table.Column | Q1: Found In Mapping?
A2: ACCOUNTS | B2: 0 | C2: ACCOUNTS | D2: ACCT | E2: TEXT | F2: 3 | G2: 0 | H2: 0 | K2: 0 | N2: 0 | O2: 0 | P2: =_xlfn.CONCAT(A2,".",D2) -> ACCOUNTS.ACCT | Q2: =VLOOKUP(Cobra8.5[[#This Row],[Table.Column]],ColumnMapping[Old Table.Column],1,) -> ACCOUNTS.ACCT
A3: ACCOUNTS | B3: 0 | C3: ACCOUNTS | D3: ACCTDESC | E3: TEXT | F3: 254 | G3: 0 | H3: 0 | K3: 0 | N3: 0 | O3: 0 | P3: =_xlfn.CONCAT(A3,".",D3) -> ACCOUNTS.ACCTDESC | Q3: =VLOOKUP(Cobra8.5[[#This Row],[Table.Column]],ColumnMapping[Old Table.Column],1,) -> ACCOUNTS.ACCTDESC
A4: ACCOUNTS | B4: 0 | C4: ACCOUNTS | D4: PROGRAM | E4: TEXT | F4: 22 | G4: 0 | H4: 0 | K4: 0 | N4: 0 | O4: 0 | P4: =_xlfn.CONCAT(A4,".",D4) -> ACCOUNTS.PROGRAM | Q4: =VLOOKUP(Cobra8.5[[#This Row],[Table.Column]],ColumnMapping[Old Table.Column],1,) -> ACCOUNTS.PROGRAM
A5: ACCOUNTS | B5: 0 | C5: ACCOUNTS | D5: REQUIRED | E5: INTE | F5: -1 | G5: 0 | H5: 0 | K5: 0 | N5: 0 | O5: 0 | P5: =_xlfn.CONCAT(A5,".",D5) -> ACCOUNTS.REQUIRED | Q5: =VLOOKUP(Cobra8.5[[#This Row],[Table.Column]],ColumnMapping[Old Table.Column],1,) -> ACCOUNTS.REQUIRED
A6: APPBE | B6: 0 | C6: APPBE | D6: CALCFILE | E6: TEXT | F6: 22 | G6: 0 | H6: 0 | K6: 0 | N6: 0 | O6: 0 | P6: =_xlfn.CONCAT(A6,".",D6) -> APPBE.CALCFILE | Q6: =VLOOKUP(Cobra8.5[[#This Row],[Table.Column]],ColumnMapping[Old Table.Column],1,) -> APPBE.CALCFILE
A7: APPBE | B7: 0 | C7: APPBE | D7: CALCORDER | E7: INTE | F7: -1 | G7: 0 | H7: 0 | K7: 0 | N7: 0 | O7: 0 | P7: =_xlfn.CONCAT(A7,".",D7) -> APPBE.CALCORDER | Q7: =VLOOKUP(Cobra8.5[[#This Row],[Table.Column]],ColumnMapping[Old Table.Column],1,) -> APPBE.CALCORDER
A8: APPBE | B8: 0 | C8: APPBE | D8: CECODE | E8: TEXT | F8: 59 | G8: 0 | H8: 0 | K8: 0 | N8: 0 | O8: 0 | P8: =_xlfn.CONCAT(A8,".",D8) -> APPBE.CECODE | Q8: =VLOOKUP(Cobra8.5[[#This Row],[Table.Column]],ColumnMapping[Old Table.Column],1,) -> APPBE.CECODE
A9: APPBE | B9: 0 | C9: APPBE | D9: LASTUPDATE | E9: DATE | F9: -1 | G9: 0 | H9: 0 | K9: 0 | N9: 0 | O9: 0 | P9: =_xlfn.CONCAT(A9,".",D9) -> APPBE.LASTUPDATE | Q9: =VLOOKUP(Cobra8.5[[#This Row],[Table.Column]],ColumnMapping[Old Table.Column],1,) -> APPBE.LASTUPDATE
A10: APPBE | B10: 0 | C10: APPBE | D10: RESULT | E10: TEXT | F10: 10 | G10: 0 | H10: 0 | K10: 0 | N10: 0 | O10: 0 | P10: =_xlfn.CONCAT(A10,".",D10) -> APPBE.RESULT | Q10: =VLOOKUP(Cobra8.5[[#This Row],[Table.Column]],ColumnMapping[Old Table.Column],1,) -> APPBE.RESULT
A11: APPBE | B11: 0 | C11: APPBE | D11: SEQUENCE | E11: INTE | F11: -1 | G11: 0 | H11: 0 | K11: 0 | N11: 0 | O11: 0 | P11: =_xlfn.CONCAT(A11,".",D11) -> APPBE.SEQUENCE | Q11: =VLOOKUP(Cobra8.5[[#This Row],[Table.Column]],ColumnMapping[Old Table.Column],1,) -> APPBE.SEQUENCE
A12: APPBE | B12: 0 | C12: APPBE | D12: USR_ID | E12: TEXT | F12: 20 | G12: 0 | H12: 0 | K12: 0 | N12: 0 | O12: 0 | P12: =_xlfn.CONCAT(A12,".",D12) -> APPBE.USR_ID | Q12: =VLOOKUP(Cobra8.5[[#This Row],[Table.Column]],ColumnMapping[Old Table.Column],1,) -> APPBE.USR_ID
A13: APPBEDTL | B13: 0 | C13: APPBEDTL | D13: CALCFILE | E13: TEXT | F13: 22 | G13: 0 | H13: 0 | K13: 0 | N13: 0 | O13: 0 | P13: =_xlfn.CONCAT(A13,".",D13) -> APPBEDTL.CALCFILE | Q13: =VLOOKUP(Cobra8.5[[#This Row],[Table.Column]],ColumnMapping[Old Table.Column],1,) -> APPBEDTL.CALCFILE
... A272: CALCDETL | B272: 0 | C272: CALCDETL | D272: SEQUENCE | E272: INTE | F272: -1 | G272: 0 | H272: 0 | K272: 0 | N272: 0 | O272: 0 | P272: =_xlfn.CONCAT(A272,".",D272) -> CALCDETL.SEQUENCE | Q272: =VLOOKUP(Cobra8.5[[#This Row],[Table.Column]],ColumnMapping[Old Table.Column],1,) -> CALCDETL.SEQUENCE
A273: CALCDETL | C273: CALCDETL | D273: SORT_CODE | E273: TEXT | F273: 1 | G273: 0 | H273: 0 | K273: 0 | N273: 0 | O273: 0 | P273: =_xlfn.CONCAT(A273,".",D273) -> CALCDETL.SORT_CODE | Q273: =VLOOKUP(Cobra8.5[[#This Row],[Table.Column]],ColumnMapping[Old Table.Column],1,) -> CALCDETL.SORT_CODE
A274: CALCDETL | B274: 0 | C274: CALCDETL | D274: SOURCE1 | E274: TEXT | F274: 10 | G274: 0 | H274: 0 | K274: 0 | N274: 0 | O274: 0 | P274: =_xlfn.CONCAT(A274,".",D274) -> CALCDETL.SOURCE1 | Q274: =VLOOKUP(Cobra8.5[[#This Row],[Table.Column]],ColumnMapping[Old Table.Column],1,) -> #N/A
A275: CALCDETL | B275: 0 | C275: CALCDETL | D275: SOURCE10 | E275: TEXT | F275: 10 | G275: 0 | H275: 0 | K275: 0 | N275: 0 | O275: 0 | P275: =_xlfn.CONCAT(A275,".",D275) -> CALCDETL.SOURCE10 | Q275: =VLOOKUP(Cobra8.5[[#This Row],[Table.Column]],ColumnMapping[Old Table.Column],1,) -> #N/A
A276: CALCDETL | B276: 0 | C276: CALCDETL | D276: SOURCE2 | E276: TEXT | F276: 10 | G276: 0 | H276: 0 | K276: 0 | N276: 0 | O276: 0 | P276: =_xlfn.CONCAT(A276,".",D276) -> CALCDETL.SOURCE2 | Q276: =VLOOKUP(Cobra8.5[[#This Row],[Table.Column]],ColumnMapping[Old Table.Column],1,) -> #N/A
A277: CALCDETL | B277: 0 | C277: CALCDETL | D277: SOURCE3 | E277: TEXT | F277: 10 | G277: 0 | H277: 0 | K277: 0 | N277: 0 | O277: 0 | P277: =_xlfn.CONCAT(A277,".",D277) -> CALCDETL.SOURCE3 | Q277: =VLOOKUP(Cobra8.5[[#This Row],[Table.Column]],ColumnMapping[Old Table.Column],1,) -> #N/A
A278: CALCDETL | B278: 0 | C278: CALCDETL | D278: SOURCE4 | E278: TEXT | F278: 10 | G278: 0 | H278: 0 | K278: 0 | N278: 0 | O278: 0 | P278: =_xlfn.CONCAT(A278,".",D278) -> CALCDETL.SOURCE4 | Q278: =VLOOKUP(Cobra8.5[[#This Row],[Table.Column]],ColumnMapping[Old Table.Column],1,) -> #N/A
A279: CALCDETL | B279: 0 | C279: CALCDETL | D279: SOURCE5 | E279: TEXT | F279: 10 | G279: 0 | H279: 0 | K279: 0 | N279: 0 | O279: 0 | P279: =_xlfn.CONCAT(A279,".",D279) -> CALCDETL.SOURCE5 | Q279: =VLOOKUP(Cobra8.5[[#This Row],[Table.Column]],ColumnMapping[Old Table.Column],1,) -> #N/A
A280: CALCDETL | B280: 0 | C280: CALCDETL | D280: SOURCE6 | E280: TEXT | F280: 10 | G280: 0 | H280: 0 | K280: 0 | N280: 0 | O280: 0 | P280: =_xlfn.CONCAT(A280,".",D280) -> CALCDETL.SOURCE6 | Q280: =VLOOKUP(Cobra8.5[[#This Row],[Table.Column]],ColumnMapping[Old Table.Column],1,) -> #N/A
A281: CALCDETL | B281: 0 | C281: CALCDETL | D281: SOURCE7 | E281: TEXT | F281: 10 | G281: 0 | H281: 0 | K281: 0 | N281: 0 | O281: 0 | P281: =_xlfn.CONCAT(A281,".",D281) -> CALCDETL.SOURCE7 | Q281: =VLOOKUP(Cobra8.5[[#This Row],[Table.Column]],ColumnMapping[Old Table.Column],1,) -> #N/A
A282: CALCDETL | B282: 0 | C282: CALCDETL | D282: SOURCE8 | E282: TEXT | F282: 10 | G282: 0 | H282: 0 | K282: 0 | N282: 0 | O282: 0 | P282: =_xlfn.CONCAT(A282,".",D282) -> CALCDETL.SOURCE8 | Q282: =VLOOKUP(Cobra8.5[[#This Row],[Table.Column]],ColumnMapping[Old Table.Column],1,) -> #N/A
A283: CALCDETL | B283: 0 | C283: CALCDETL | D283: SOURCE9 | E283: TEXT | F283: 10 | G283: 0 | H283: 0 | K283: 0 | N283: 0 | O283: 0 | P283: =_xlfn.CONCAT(A283,".",D283) -> CALCDETL.SOURCE9 | Q283: =VLOOKUP(Cobra8.5[[#This Row],[Table.Column]],ColumnMapping[Old Table.Column],1,) -> #N/A
A284: CALCDETL | B284: 0 | C284: CALCDETL | D284: UNITS | E284: TEXT | F284: 10 | G284: 0 | H284: 0 | K284: 0 | N284: 0 | O284: 0 | P284: =_xlfn.CONCAT(A284,".",D284) -> CALCDETL.UNITS | Q284: =VLOOKUP(Cobra8.5[[#This Row],[Table.Column]],ColumnMapping[Old Table.Column],1,) -> CALCDETL.UNITS
A285: CALCDETL | B285: 0 | C285: CALCDETL | D285: USR_ID | E285: TEXT | F285: 20 | G285: 0 | H285: 0 | K285: 0 | N285: 0 | O285: 0 | P285: =_xlfn.CONCAT(A285,".",D285) -> CALCDETL.USR_ID | Q285: =VLOOKUP(Cobra8.5[[#This Row],[Table.Column]],ColumnMapping[Old Table.Column],1,) -> CALCDETL.USR_ID
... A952: WST_CDR | B952: 7 | C952: CDR | D952: DESCRIPTION | E952: TEXT | F952: 125 | G952: 0 | H952: 0 | K952: 30245 | N952: 0 | O952: 0 | P952: =_xlfn.CONCAT(A952,".",D952) -> WST_CDR.DESCRIPTION | Q952: =VLOOKUP(Cobra8.5[[#This Row],[Table.Column]],ColumnMapping[Old Table.Column],1,) -> #N/A
A953: WST_CDR | B953: 7 | C953: CDR | D953: DIR_UID | E953: GUID | F953: 22 | G953: 0 | H953: 0 | K953: 712 | L953: COD | M953: DIR_UID | N953: 1 | O953: 0 | P953: =_xlfn.CONCAT(A953,".",D953) -> WST_CDR.DIR_UID | Q953: =VLOOKUP(Cobra8.5[[#This Row],[Table.Column]],ColumnMapping[Old Table.Column],1,) -> #N/A
A954: WST_CDR | B954: 7 | C954: CDR | D954: INTEGRATION_ID | E954: INTE | F954: 10 | G954: 0 | H954: 0 | K954: 31947 | N954: 0 | O954: 0 | P954: =_xlfn.CONCAT(A954,".",D954) -> WST_CDR.INTEGRATION_ID | Q954: =VLOOKUP(Cobra8.5[[#This Row],[Table.Column]],ColumnMapping[Old Table.Column],1,) -> #N/A
A955: WST_CDR | B955: 7 | C955: CDR | D955: LASTUPDATE | E955: DATE | F955: 20 | G955: 0 | H955: 131072 | K955: 30460 | N955: 0 | O955: 0 | P955: =_xlfn.CONCAT(A955,".",D955) -> WST_CDR.LASTUPDATE | Q955: =VLOOKUP(Cobra8.5[[#This Row],[Table.Column]],ColumnMapping[Old Table.Column],1,) -> #N/A
A956: WST_CDR | B956: 7 | C956: CDR | D956: POSITION_NUM | E956: INTE | F956: 8 | G956: 0 | H956: 0 | K956: 30248 | N956: 0 | O956: 0 | P956: =_xlfn.CONCAT(A956,".",D956) -> WST_CDR.POSITION_NUM | Q956: =VLOOKUP(Cobra8.5[[#This Row],[Table.Column]],ColumnMapping[Old Table.Column],1,) -> #N/A
A957: WST_CDR | B957: 7 | C957: CDR | D957: SEQUENCE | E957: INTE | F957: 4 | G957: 0 | H957: 196608 | K957: 30042 | N957: 0 | O957: 0 | P957: =_xlfn.CONCAT(A957,".",D957) -> WST_CDR.SEQUENCE | Q957: =VLOOKUP(Cobra8.5[[#This Row],[Table.Column]],ColumnMapping[Old Table.Column],1,) -> #N/A
A958: WST_CDR | B958: 7 | C958: CDR | D958: SUPPRESS | E958: BOOL | F958: 4 | G958: 0 | H958: 0 | K958: 30332 | N958: 0 | O958: 0 | P958: =_xlfn.CONCAT(A958,".",D958) -> WST_CDR.SUPPRESS | Q958: =VLOOKUP(Cobra8.5[[#This Row],[Table.Column]],ColumnMapping[Old Table.Column],1,) -> #N/A
A959: WST_CDR | B959: 7 | C959: CDR | D959: USR_ID | E959: TEXT | F959: 20 | G959: 0 | H959: 131072 | K959: 30451 | N959: 0 | O959: 0 | P959: =_xlfn.CONCAT(A959,".",D959) -> WST_CDR.USR_ID | Q959: =VLOOKUP(Cobra8.5[[#This Row],[Table.Column]],ColumnMapping[Old Table.Column],1,) -> #N/A
A960: WST_CFG | B960: 2 | C960: CFG | D960: CFG_ID | E960: TEXT | F960: 60 | G960: 0 | H960: 0 | K960: 0 | N960: 0 | O960: 0 | P960: =_xlfn.CONCAT(A960,".",D960) -> WST_CFG.CFG_ID | Q960: =VLOOKUP(Cobra8.5[[#This Row],[Table.Column]],ColumnMapping[Old Table.Column],1,) -> #N/A
A961: WST_CFG | B961: 2 | C961: CFG | D961: CFG_TYPE | E961: TEXT | F961: 30 | G961: 0 | H961: 0 | K961: 0 | N961: 0 | O961: 0 | P961: =_xlfn.CONCAT(A961,".",D961) -> WST_CFG.CFG_TYPE | Q961: =VLOOKUP(Cobra8.5[[#This Row],[Table.Column]],ColumnMapping[Old Table.Column],1,) -> #N/A
A962: WST_CFG | B962: 2 | C962: CFG | D962: CFG_UID | E962: GUID | F962: 22 | G962: 0 | H962: 0 | K962: 0 | N962: 0 | O962: 0 | P962: =_xlfn.CONCAT(A962,".",D962) -> WST_CFG.CFG_UID | Q962: =VLOOKUP(Cobra8.5[[#This Row],[Table.Column]],ColumnMapping[Old Table.Column],1,) -> #N/A
A963: WST_CFG | B963: 2 | C963: CFG | D963: DATA | E963: TEXT | F963: 8192 | G963: 0 | H963: 0 | K963: 0 | N963: 0 | O963: 0 | P963: =_xlfn.CONCAT(A963,".",D963) -> WST_CFG.DATA | Q963: =VLOOKUP(Cobra8.5[[#This Row],[Table.Column]],ColumnMapping[Old Table.Column],1,) -> #N/A
A964: WST_CFG | B964: 2 | C964: CFG | D964: DESCRIPTION | E964: TEXT | F964: 254 | G964: 0 | H964: 0 | K964: 0 | N964: 0 | O964: 0 | P964: =_xlfn.CONCAT(A964,".",D964) -> WST_CFG.DESCRIPTION | Q964: =VLOOKUP(Cobra8.5[[#This Row],[Table.Column]],ColumnMapping[Old Table.Column],1,) -> #N/A
...

Sheet Cobra 8.6
A1: TABLE_NAME | B1: TABLE_FLAGS | C1: TABLE_TYPE | D1: FLD_NAME | E1: TYPE | F1: LENGTH | G1: SCALE | H1: COL_FLAGS | I1: SYS_NAME | J1: USR_NAME | K1: STRING_ID | L1: FKEY_TABLE | M1: FKEY_FLD_NAME | N1: FKEY_REQUIRED | O1: FKEY_VIRTUAL | P1: Table.Column | Q1: Found In Mapping?
A2: ACCOUNTS | B2: 0 | C2: ACCOUNTS | D2: ACCT | E2: TEXT | F2: 3 | G2: 0 | H2: 0 | K2: 0 | N2: 0 | O2: 0 | P2: =_xlfn.CONCAT(A2,".",D2) -> ACCOUNTS.ACCT | Q2: =VLOOKUP(Cobra8.6[[#This Row],[Table.Column]],ColumnMapping[Old Table.Column],1,) -> ACCOUNTS.ACCT
A3: ACCOUNTS | B3: 0 | C3: ACCOUNTS | D3: ACCTDESC | E3: TEXT | F3: 254 | G3: 0 | H3: 0 | K3: 0 | N3: 0 | O3: 0 | P3: =_xlfn.CONCAT(A3,".",D3) -> ACCOUNTS.ACCTDESC | Q3: =VLOOKUP(Cobra8.6[[#This Row],[Table.Column]],ColumnMapping[Old Table.Column],1,) -> ACCOUNTS.ACCTDESC
A4: ACCOUNTS | B4: 0 | C4: ACCOUNTS | D4: PROGRAM | E4: TEXT | F4: 22 | G4: 0 | H4: 0 | K4: 0 | N4: 0 | O4: 0 | P4: =_xlfn.CONCAT(A4,".",D4) -> ACCOUNTS.PROGRAM | Q4: =VLOOKUP(Cobra8.6[[#This Row],[Table.Column]],ColumnMapping[Old Table.Column],1,) -> ACCOUNTS.PROGRAM
A5: ACCOUNTS | B5: 0 | C5: ACCOUNTS | D5: REQUIRED | E5: INTE | F5: -1 | G5: 0 | H5: 0 | K5: 0 | N5: 0 | O5: 0 | P5: =_xlfn.CONCAT(A5,".",D5) -> ACCOUNTS.REQUIRED | Q5: =VLOOKUP(Cobra8.6[[#This Row],[Table.Column]],ColumnMapping[Old Table.Column],1,) -> ACCOUNTS.REQUIRED
A6: APPBE | B6: 0 | C6: APPBE | D6: CALCFILE | E6: TEXT | F6: 22 | G6: 0 | H6: 0 | K6: 0 | N6: 0 | O6: 0 | P6: =_xlfn.CONCAT(A6,".",D6) -> APPBE.CALCFILE | Q6: =VLOOKUP(Cobra8.6[[#This Row],[Table.Column]],ColumnMapping[Old Table.Column],1,) -> APPBE.CALCFILE
A7: APPBE | B7: 0 | C7: APPBE | D7: CALCORDER | E7: INTE | F7: -1 | G7: 0 | H7: 0 | K7: 0 | N7: 0 | O7: 0 | P7: =_xlfn.CONCAT(A7,".",D7) -> APPBE.CALCORDER | Q7: =VLOOKUP(Cobra8.6[[#This Row],[Table.Column]],ColumnMapping[Old Table.Column],1,) -> APPBE.CALCORDER
A8: APPBE | B8: 0 | C8: APPBE | D8: CECODE | E8: TEXT | F8: 59 | G8: 0 | H8: 0 | K8: 0 | N8: 0 | O8: 0 | P8: =_xlfn.CONCAT(A8,".",D8) -> APPBE.CECODE | Q8: =VLOOKUP(Cobra8.6[[#This Row],[Table.Column]],ColumnMapping[Old Table.Column],1,) -> APPBE.CECODE
A9: APPBE | B9: 0 | C9: APPBE | D9: LASTUPDATE | E9: DATE | F9: -1 | G9: 0 | H9: 0 | K9: 0 | N9: 0 | O9: 0 | P9: =_xlfn.CONCAT(A9,".",D9) -> APPBE.LASTUPDATE | Q9: =VLOOKUP(Cobra8.6[[#This Row],[Table.Column]],ColumnMapping[Old Table.Column],1,) -> APPBE.LASTUPDATE
A10: APPBE | B10: 0 | C10: APPBE | D10: RESULT | E10: TEXT | F10: 10 | G10: 0 | H10: 0 | K10: 0 | N10: 0 | O10: 0 | P10: =_xlfn.CONCAT(A10,".",D10) -> APPBE.RESULT | Q10: =VLOOKUP(Cobra8.6[[#This Row],[Table.Column]],ColumnMapping[Old Table.Column],1,) -> APPBE.RESULT
A11: APPBE | B11: 0 | C11: APPBE | D11: SEQUENCE | E11: INTE | F11: -1 | G11: 0 | H11: 0 | K11: 0 | N11: 0 | O11: 0 | P11: =_xlfn.CONCAT(A11,".",D11) -> APPBE.SEQUENCE | Q11: =VLOOKUP(Cobra8.6[[#This Row],[Table.Column]],ColumnMapping[Old Table.Column],1,) -> APPBE.SEQUENCE
A12: APPBE | B12: 0 | C12: APPBE | D12: USR_ID | E12: TEXT | F12: 20 | G12: 0 | H12: 0 | K12: 0 | N12: 0 | O12: 0 | P12: =_xlfn.CONCAT(A12,".",D12) -> APPBE.USR_ID | Q12: =VLOOKUP(Cobra8.6[[#This Row],[Table.Column]],ColumnMapping[Old Table.Column],1,) -> APPBE.USR_ID
A13: APPBEDTL | B13: 0 | C13: APPBEDTL | D13: CALCFILE | E13: TEXT | F13: 22 | G13: 0 | H13: 0 | K13: 0 | N13: 0 | O13: 0 | P13: =_xlfn.CONCAT(A13,".",D13) -> APPBEDTL.CALCFILE | Q13: =VLOOKUP(Cobra8.6[[#This Row],[Table.Column]],ColumnMapping[Old Table.Column],1,) -> APPBEDTL.CALCFILE
... A272: CALCDETL | B272: 0 | C272: CALCDETL | D272: SEQUENCE | E272: INTE | F272: -1 | G272: 0 | H272: 0 | K272: 0 | N272: 0 | O272: 0 | P272: =_xlfn.CONCAT(A272,".",D272) -> CALCDETL.SEQUENCE | Q272: =VLOOKUP(Cobra8.6[[#This Row],[Table.Column]],ColumnMapping[Old Table.Column],1,) -> CALCDETL.SEQUENCE
A273: CALCDETL | C273: CALCDETL | D273: SORT_CODE | E273: TEXT | F273: 1 | G273: 0 | H273: 0 | K273: 0 | N273: 0 | O273: 0 | P273: =_xlfn.CONCAT(A273,".",D273) -> CALCDETL.SORT_CODE | Q273: =VLOOKUP(Cobra8.6[[#This Row],[Table.Column]],ColumnMapping[Old Table.Column],1,) -> CALCDETL.SORT_CODE
A274: CALCDETL | B274: 0 | C274: CALCDETL | D274: SOURCE1 | E274: TEXT | F274: 10 | G274: 0 | H274: 0 | K274: 0 | N274: 0 | O274: 0 | P274: =_xlfn.CONCAT(A274,".",D274) -> CALCDETL.SOURCE1 | Q274: =VLOOKUP(Cobra8.6[[#This Row],[Table.Column]],ColumnMapping[Old Table.Column],1,) -> #N/A
A275: CALCDETL | B275: 0 | C275: CALCDETL | D275: SOURCE10 | E275: TEXT | F275: 10 | G275: 0 | H275: 0 | K275: 0 | N275: 0 | O275: 0 | P275: =_xlfn.CONCAT(A275,".",D275) -> CALCDETL.SOURCE10 | Q275: =VLOOKUP(Cobra8.6[[#This Row],[Table.Column]],ColumnMapping[Old Table.Column],1,) -> #N/A
A276: CALCDETL | B276: 0 | C276: CALCDETL | D276: SOURCE2 | E276: TEXT | F276: 10 | G276: 0 | H276: 0 | K276: 0 | N276: 0 | O276: 0 | P276: =_xlfn.CONCAT(A276,".",D276) -> CALCDETL.SOURCE2 | Q276: =VLOOKUP(Cobra8.6[[#This Row],[Table.Column]],ColumnMapping[Old Table.Column],1,) -> #N/A
A277: CALCDETL | B277: 0 | C277: CALCDETL | D277: SOURCE3 | E277: TEXT | F277: 10 | G277: 0 | H277: 0 | K277: 0 | N277: 0 | O277: 0 | P277: =_xlfn.CONCAT(A277,".",D277) -> CALCDETL.SOURCE3 | Q277: =VLOOKUP(Cobra8.6[[#This Row],[Table.Column]],ColumnMapping[Old Table.Column],1,) -> #N/A
A278: CALCDETL | B278: 0 | C278: CALCDETL | D278: SOURCE4 | E278: TEXT | F278: 10 | G278: 0 | H278: 0 | K278: 0 | N278: 0 | O278: 0 | P278: =_xlfn.CONCAT(A278,".",D278) -> CALCDETL.SOURCE4 | Q278: =VLOOKUP(Cobra8.6[[#This Row],[Table.Column]],ColumnMapping[Old Table.Column],1,) -> #N/A
A279: CALCDETL | B279: 0 | C279: CALCDETL | D279: SOURCE5 | E279: TEXT | F279: 10 | G279: 0 | H279: 0 | K279: 0 | N279: 0 | O279: 0 | P279: =_xlfn.CONCAT(A279,".",D279) -> CALCDETL.SOURCE5 | Q279: =VLOOKUP(Cobra8.6[[#This Row],[Table.Column]],ColumnMapping[Old Table.Column],1,) -> #N/A
A280: CALCDETL | B280: 0 | C280: CALCDETL | D280: SOURCE6 | E280: TEXT | F280: 10 | G280: 0 | H280: 0 | K280: 0 | N280: 0 | O280: 0 | P280: =_xlfn.CONCAT(A280,".",D280) -> CALCDETL.SOURCE6 | Q280: =VLOOKUP(Cobra8.6[[#This Row],[Table.Column]],ColumnMapping[Old Table.Column],1,) -> #N/A
A281: CALCDETL | B281: 0 | C281: CALCDETL | D281: SOURCE7 | E281: TEXT | F281: 10 | G281: 0 | H281: 0 | K281: 0 | N281: 0 | O281: 0 | P281: =_xlfn.CONCAT(A281,".",D281) -> CALCDETL.SOURCE7 | Q281: =VLOOKUP(Cobra8.6[[#This Row],[Table.Column]],ColumnMapping[Old Table.Column],1,) -> #N/A
A282: CALCDETL | B282: 0 | C282: CALCDETL | D282: SOURCE8 | E282: TEXT | F282: 10 | G282: 0 | H282: 0 | K282: 0 | N282: 0 | O282: 0 | P282: =_xlfn.CONCAT(A282,".",D282) -> CALCDETL.SOURCE8 | Q282: =VLOOKUP(Cobra8.6[[#This Row],[Table.Column]],ColumnMapping[Old Table.Column],1,) -> #N/A
A283: CALCDETL | B283: 0 | C283: CALCDETL | D283: SOURCE9 | E283: TEXT | F283: 10 | G283: 0 | H283: 0 | K283: 0 | N283: 0 | O283: 0 | P283: =_xlfn.CONCAT(A283,".",D283) -> CALCDETL.SOURCE9 | Q283: =VLOOKUP(Cobra8.6[[#This Row],[Table.Column]],ColumnMapping[Old Table.Column],1,) -> #N/A
A284: CALCDETL | B284: 0 | C284: CALCDETL | D284: UNITS | E284: TEXT | F284: 10 | G284: 0 | H284: 0 | K284: 0 | N284: 0 | O284: 0 | P284: =_xlfn.CONCAT(A284,".",D284) -> CALCDETL.UNITS | Q284: =VLOOKUP(Cobra8.6[[#This Row],[Table.Column]],ColumnMapping[Old Table.Column],1,) -> CALCDETL.UNITS
A285: CALCDETL | B285: 0 | C285: CALCDETL | D285: USR_ID | E285: TEXT | F285: 20 | G285: 0 | H285: 0 | K285: 0 | N285: 0 | O285: 0 | P285: =_xlfn.CONCAT(A285,".",D285) -> CALCDETL.USR_ID | Q285: =VLOOKUP(Cobra8.6[[#This Row],[Table.Column]],ColumnMapping[Old Table.Column],1,) -> CALCDETL.USR_ID
... A952: WST_CDR | B952: 7 | C952: CDR | D952: DESCRIPTION | E952: TEXT | F952: 125 | G952: 0 | H952: 0 | K952: 30245 | N952: 0 | O952: 0 | P952: =_xlfn.CONCAT(A952,".",D952) -> WST_CDR.DESCRIPTION | Q952: =VLOOKUP(Cobra8.6[[#This Row],[Table.Column]],ColumnMapping[Old Table.Column],1,) -> #N/A
A953: WST_CDR | B953: 7 | C953: CDR | D953: DIR_UID | E953: GUID | F953: 22 | G953: 0 | H953: 0 | K953: 712 | L953: COD | M953: DIR_UID | N953: 1 | O953: 0 | P953: =_xlfn.CONCAT(A953,".",D953) -> WST_CDR.DIR_UID | Q953: =VLOOKUP(Cobra8.6[[#This Row],[Table.Column]],ColumnMapping[Old Table.Column],1,) -> #N/A
A954: WST_CDR | B954: 7 | C954: CDR | D954: INTEGRATION_ID | E954: INTE | F954: 10 | G954: 0 | H954: 0 | K954: 31947 | N954: 0 | O954: 0 | P954: =_xlfn.CONCAT(A954,".",D954) -> WST_CDR.INTEGRATION_ID | Q954: =VLOOKUP(Cobra8.6[[#This Row],[Table.Column]],ColumnMapping[Old Table.Column],1,) -> #N/A
A955: WST_CDR | B955: 7 | C955: CDR | D955: LASTUPDATE | E955: DATE | F955: 20 | G955: 0 | H955: 131072 | K955: 30460 | N955: 0 | O955: 0 | P955: =_xlfn.CONCAT(A955,".",D955) -> WST_CDR.LASTUPDATE | Q955: =VLOOKUP(Cobra8.6[[#This Row],[Table.Column]],ColumnMapping[Old Table.Column],1,) -> #N/A
A956: WST_CDR | B956: 7 | C956: CDR | D956: POSITION_NUM | E956: INTE | F956: 8 | G956: 0 | H956: 0 | K956: 30248 | N956: 0 | O956: 0 | P956: =_xlfn.CONCAT(A956,".",D956) -> WST_CDR.POSITION_NUM | Q956: =VLOOKUP(Cobra8.6[[#This Row],[Table.Column]],ColumnMapping[Old Table.Column],1,) -> #N/A
A957: WST_CDR | B957: 7 | C957: CDR | D957: SEQUENCE | E957: INTE | F957: 4 | G957: 0 | H957: 196608 | K957: 30042 | N957: 0 | O957: 0 | P957: =_xlfn.CONCAT(A957,".",D957) -> WST_CDR.SEQUENCE | Q957: =VLOOKUP(Cobra8.6[[#This Row],[Table.Column]],ColumnMapping[Old Table.Column],1,) -> #N/A
A958: WST_CDR | B958: 7 | C958: CDR | D958: SUPPRESS | E958: BOOL | F958: 4 | G958: 0 | H958: 0 | K958: 30332 | N958: 0 | O958: 0 | P958: =_xlfn.CONCAT(A958,".",D958) -> WST_CDR.SUPPRESS | Q958: =VLOOKUP(Cobra8.6[[#This Row],[Table.Column]],ColumnMapping[Old Table.Column],1,) -> #N/A
A959: WST_CDR | B959: 7 | C959: CDR | D959: USR_ID | E959: TEXT | F959: 20 | G959: 0 | H959: 131072 | K959: 30451 | N959: 0 | O959: 0 | P959: =_xlfn.CONCAT(A959,".",D959) -> WST_CDR.USR_ID | Q959: =VLOOKUP(Cobra8.6[[#This Row],[Table.Column]],ColumnMapping[Old Table.Column],1,) -> #N/A
A960: WST_CFG | B960: 2 | C960: CFG | D960: CFG_ID | E960: TEXT | F960: 60 | G960: 0 | H960: 0 | K960: 0 | N960: 0 | O960: 0 | P960: =_xlfn.CONCAT(A960,".",D960) -> WST_CFG.CFG_ID | Q960: =VLOOKUP(Cobra8.6[[#This Row],[Table.Column]],ColumnMapping[Old Table.Column],1,) -> #N/A
A961: WST_CFG | B961: 2 | C961: CFG | D961: CFG_TYPE | E961: TEXT | F961: 30 | G961: 0 | H961: 0 | K961: 0 | N961: 0 | O961: 0 | P961: =_xlfn.CONCAT(A961,".",D961) -> WST_CFG.CFG_TYPE | Q961: =VLOOKUP(Cobra8.6[[#This Row],[Table.Column]],ColumnMapping[Old Table.Column],1,) -> #N/A
A962: WST_CFG | B962: 2 | C962: CFG | D962: CFG_UID | E962: GUID | F962: 22 | G962: 0 | H962: 0 | K962: 0 | N962: 0 | O962: 0 | P962: =_xlfn.CONCAT(A962,".",D962) -> WST_CFG.CFG_UID | Q962: =VLOOKUP(Cobra8.6[[#This Row],[Table.Column]],ColumnMapping[Old Table.Column],1,) -> #N/A
A963: WST_CFG | B963: 2 | C963: CFG | D963: DATA | E963: TEXT | F963: 8192 | G963: 0 | H963: 0 | K963: 0 | N963: 0 | O963: 0 | P963: =_xlfn.CONCAT(A963,".",D963) -> WST_CFG.DATA | Q963: =VLOOKUP(Cobra8.6[[#This Row],[Table.Column]],ColumnMapping[Old Table.Column],1,) -> #N/A
A964: WST_CFG | B964: 2 | C964: CFG | D964: DESCRIPTION | E964: TEXT | F964: 254 | G964: 0 | H964: 0 | K964: 0 | N964: 0 | O964: 0 | P964: =_xlfn.CONCAT(A964,".",D964) -> WST_CFG.DESCRIPTION | Q964: =VLOOKUP(Cobra8.6[[#This Row],[Table.Column]],ColumnMapping[Old Table.Column],1,) -> #N/A
...

Sheet 8.5 -> Web Table Mapping
A1: Old Table Name | B1: New Table Name | C1: Migrate | D1: Comment | E1: VIEW - Creates view with OLD table name | F1: Legend | G1: Hybridization
A2: ACCOUNTS | C2: [ NONE ] | D2: Obsolete | E2: =IF(AND(A2<>"",B2<>""),_xlfn.CONCAT("CREATE OR REPLACE VIEW ",A2," AS SELECT * FROM ",B2,";"),"") | F2: [ NONE ] = Table not created in Cobra Web. | G2: Y
A3: APPBE | C3: [ FUTURE ] | D3: Apportionment not planned for Cobra Web 1.0 | E3: =IF(AND(A3<>"",B3<>""),_xlfn.CONCAT("CREATE OR REPLACE VIEW ",A3," AS SELECT * FROM ",B3,";"),"") | F3: [ FUTURE ] = Table not needed for Cobra Web 1.0. | G3: Not Required
A4: APPBEDTL | C4: [ FUTURE ] | D4: Apportionment not planned for Cobra Web 1.0 | E4: =IF(AND(A4<>"",B4<>""),_xlfn.CONCAT("CREATE OR REPLACE VIEW ",A4," AS SELECT * FROM ",B4,";"),"") | F4: [ TBD ] = We expect we'll need a table but have not yet determined what the table is or where the data might live | G4: Not Required
A5: APPMAPSC | C5: [ FUTURE ] | D5: Apportionment not planned for Cobra Web 1.0 | E5: =IF(AND(A5<>"",B5<>""),_xlfn.CONCAT("CREATE OR REPLACE VIEW ",A5," AS SELECT * FROM ",B5,";"),"") | G5: Not Required
A6: APPMAPTG | C6: [ FUTURE ] | D6: Apportionment not planned for Cobra Web 1.0 | E6: =IF(AND(A6<>"",B6<>""),_xlfn.CONCAT("CREATE OR REPLACE VIEW ",A6," AS SELECT * FROM ",B6,";"),"") | G6: Not Required
A7: BASEDETL | B7: PROJECT_AUDIT_LOG_TPHASE | D7: This table holds the time phased detail that corresponds to a change logged in the Project_Audit_Log table | E7: =IF(AND(A7<>"",B7<>""),_xlfn.CONCAT("CREATE OR REPLACE VIEW ",A7," AS SELECT * FROM ",B7,";"),"") -> CREATE OR REPLACE VIEW BASEDETL AS SELECT * FROM PROJECT_AUDIT_LOG_TPHASE; | G7: Y
A8: BASEHIST | B8: PROJECT_AUDIT_LOG_HISTORY | D8: This table represents the end of period snapshot of totals for Control Accounts and Work Packages only. Note: I think this table might eventually go away and instead we'll take a snapshot of the materialized view of totals at period end, which might end up in different tables. For now, however, we will still convert this table | E8: =IF(AND(A8<>"",B8<>""),_xlfn.CONCAT("CREATE OR REPLACE VIEW ",A8," AS SELECT * FROM ",B8,";"),"") -> CREATE OR REPLACE VIEW BASEHIST AS SELECT * FROM PROJECT_AUDIT_LOG_HISTORY; | G8: Y
A9: BASELINE | B9: PROJECT_AUDIT_LOG_ACCOUNTS | D9: When a project's status date is advanced to the next period, we take a snapshot of the Project Account totals for the current period and store them in this table. | E9: =IF(AND(A9<>"",B9<>""),_xlfn.CONCAT("CREATE OR REPLACE VIEW ",A9," AS SELECT * FROM ",B9,";"),"") -> CREATE OR REPLACE VIEW BASELINE AS SELECT * FROM PROJECT_AUDIT_LOG_ACCOUNTS; | G9: Y
A10: BASELOG | B10: PROJECT_AUDIT_LOG | D10: Note 1: I think there was a situation where we got an entry added to this table other than when advancing the project status. Stewart will remember. | E10: =IF(AND(A10<>"",B10<>""),_xlfn.CONCAT("CREATE OR REPLACE VIEW ",A10," AS SELECT * FROM ",B10,";"),"") -> CREATE OR REPLACE VIEW BASELOG AS SELECT * FROM PROJECT_AUDIT_LOG; | G10: Y
A11: BATCH | C11: [ NONE ] | D11: Replaced by Reporting service | E11: =IF(AND(A11<>"",B11<>""),_xlfn.CONCAT("CREATE OR REPLACE VIEW ",A11," AS SELECT * FROM ",B11,";"),"") | G11: TBD
A12: BATCHREP | C12: [ NONE ] | D12: Replaced by Reporting service | E12: =IF(AND(A12<>"",B12<>""),_xlfn.CONCAT("CREATE OR REPLACE VIEW ",A12," AS SELECT * FROM ",B12,";"),"") | G12: TBD
A13: BDNDETL | B13: CODE | E13: =IF(AND(A13<>"",B13<>""),_xlfn.CONCAT("CREATE OR REPLACE VIEW ",A13," AS SELECT * FROM ",B13,";"),"") -> CREATE OR REPLACE VIEW BDNDETL AS SELECT * FROM CODE; | G13: Not Required
A14: BDNDETL | B14: CODE_THRESHOLD | E14: =IF(AND(A14<>"",B14<>""),_xlfn.CONCAT("CREATE OR REPLACE VIEW ",A14," AS SELECT * FROM ",B14,";"),"") -> CREATE OR REPLACE VIEW BDNDETL AS SELECT * FROM CODE_THRESHOLD; | G14: Not Required
A15: BREAKDWN | B15: CODE_FILE | E15: =IF(AND(A15<>"",B15<>""),_xlfn.CONCAT("CREATE OR REPLACE VIEW ",A15," AS SELECT * FROM ",B15,";"),"") -> CREATE OR REPLACE VIEW BREAKDWN AS SELECT * FROM CODE_FILE; | G15: Not Required
A16: CALC | B16: RESOURCE_FILE | E16: =IF(AND(A16<>"",B16<>""),_xlfn.CONCAT("CREATE OR REPLACE VIEW ",A16," AS SELECT * FROM ",B16,";"),"") -> CREATE OR REPLACE VIEW CALC AS SELECT * FROM RESOURCE_FILE; | G16: Y
A17: CALCDESC | B17: RESOURCES | E17: =IF(AND(A17<>"",B17<>""),_xlfn.CONCAT("CREATE OR REPLACE VIEW ",A17," AS SELECT * FROM ",B17,";"),"") -> CREATE OR REPLACE VIEW CALCDESC AS SELECT * FROM RESOURCES; | G17: Y
A18: CALCDETL | B18: RESOURCE_COST_CALCULATION | E18: =IF(AND(A18<>"",B18<>""),_xlfn.CONCAT("CREATE OR REPLACE VIEW ",A18," AS SELECT * FROM ",B18,";"),"") -> CREATE OR REPLACE VIEW CALCDETL AS SELECT * FROM RESOURCE_COST_CALCULATION; | G18: Y
A19: CALCEXPR | C19: No | D19: This stores UI column expressions. These will change for the Web product. | E19: =IF(AND(A19<>"",B19<>""),_xlfn.CONCAT("CREATE OR REPLACE VIEW ",A19," AS SELECT * FROM ",B19,";"),"") | G19: Not Required
